<?xml version="1.0" ?>
<robot name="flexible_fish">

  <!-- head -->
  <link name="head">
    <visual>
      <geometry>
        <mesh filename="models/fish_head.obj" scale="0.04 0.04 0.04"/>
      </geometry>
      <material name="fish_material_head">
        <texture filename="models/fish_texture.jpg"/>
      </material>
    </visual>
    <collision>
      <geometry>
        <mesh filename="models/fish_head.obj" scale="0.04 0.04 0.04"/>
      </geometry>
    </collision>
  </link>

  <!-- body -->
  <link name="body">
    <visual>
      <geometry>
        <mesh filename="models/fish_body.obj" scale="0.04 0.04 0.04"/>
      </geometry>
      <material name="fish_material_body">
        <texture filename="models/fish_texture.jpg"/>
      </material>
    </visual>
    <collision>
      <geometry>
        <mesh filename="models/fish_body.obj" scale="0.04 0.04 0.04"/>
      </geometry>
    </collision>
  </link>

  <!-- tail -->
  <link name="tail">
    <visual>
      <geometry>
        <mesh filename="models/fish_tail.obj" scale="0.04 0.04 0.04"/>
      </geometry>
      <material name="fish_material_tail">
        <texture filename="models/fish_texture.jpg"/>
      </material>
    </visual>
    <collision>
      <geometry>
        <mesh filename="models/fish_tail.obj" scale="0.04 0.04 0.04"/>
      </geometry>
    </collision>
  </link>

  <!-- joint connection -->

  <!-- joint between head and body -->
  <joint name="head_to_body" type="revolute">
    <parent link="head"/>
    <child link="body"/>
    <origin xyz="0.075 0 0" rpy="0 0 0"/>
    <axis xyz="0 0 1"/>
    <limit lower="-1.57" upper="1.57" effort="1" velocity="1"/>
  </joint>

  <!-- joint between body and tail -->
  <joint name="body_to_tail" type="revolute">
    <parent link="body"/>
    <child link="tail"/>
    <origin xyz="0.04 0 0" rpy="0 0 0"/>
    <axis xyz="0 0 1"/>
    <limit lower="-1.57" upper="1.57" effort="1" velocity="1"/>
  </joint>

</robot>
